___________________________________________________________________________________________________
{'crafting_table': 1, 'BW_block': 3}
___________________________________________________________________________________________________
>>>>>>>>>>>>>>>>>>>>>> 9
7
[[2070 1607 1013 2529 1793  800  587]
 [2231 1565 1392 2300 2937 2516 1974]
 [1750 1201 1473 2535 3095 2391 4086]
 [2126  790 1108 1931 1612 1003 4398]
 [1939  536  670 1118 1283  822 3921]
 [2966 1512 1704 1811 1939 1667 4611]
 [3700 2665 2503 3366 2387 1378 2548]]
Traceback (most recent call last):
  File "C:/Users/usef2/Documents/USC/ML Delivery/RL_drone-main_traffic/Train_wandb.py", line 217, in <module>
    check_env(env, warn=True)
  File "C:\Users\usef2\anaconda3\envs\RL_drone-main\lib\site-packages\stable_baselines\common\env_checker.py", line 214, in check_env
    _check_returned_values(env, observation_space, action_space)
  File "C:\Users\usef2\anaconda3\envs\RL_drone-main\lib\site-packages\stable_baselines\common\env_checker.py", line 97, in _check_returned_values
    obs = env.reset()
  File "C:\Users\usef2\anaconda3\envs\RL_drone-main\lib\site-packages\stable_baselines\bench\monitor.py", line 80, in reset
    return self.env.reset(**kwargs)
  File "C:\Users\usef2\Documents\USC\ML Delivery\RL_drone-main_traffic\gym_novel_gridworlds\envs\novel_gridworld_v0_env.py", line 173, in reset
    self.add_item_to_map(item, ids, r=r, c=c)
  File "C:\Users\usef2\Documents\USC\ML Delivery\RL_drone-main_traffic\gym_novel_gridworlds\envs\novel_gridworld_v0_env.py", line 200, in add_item_to_map
    idx = self.available_locations.index((r, c))
ValueError: (1, 3) is not in list